Epoch:  0
  0%|                                                                                                                                               | 0/3008 [00:00<?, ?it/s]/Library/Frameworks/Python.framework/Versions/3.11/lib/python3.11/site-packages/torch/amp/autocast_mode.py:265: UserWarning: User provided device_type of 'cuda', but CUDA is not available. Disabling
  warnings.warn(
  0%|                               | 1/3008 [00:10<8:23:33, 10.05s/it, D_fake=0.304, D_real=0.498, G_loss=92.8, dice_score_G_val=0.609, style_loss_G=0.609, total_loss=92.8]
Traceback (most recent call last):
  File "/Users/mohamedmafaz/Desktop/PixSketch2Pix/train_with_style_loss.py", line 165, in <module>
    main()
  File "/Users/mohamedmafaz/Desktop/PixSketch2Pix/train_with_style_loss.py", line 154, in main
    train_fn(
  File "/Users/mohamedmafaz/Desktop/PixSketch2Pix/train_with_style_loss.py", line 60, in train_fn
    for idx, (x,z1,z2,z3,z4,y) in enumerate(loop):
  File "/Library/Frameworks/Python.framework/Versions/3.11/lib/python3.11/site-packages/tqdm/std.py", line 1178, in __iter__
    for obj in iterable:
  File "/Library/Frameworks/Python.framework/Versions/3.11/lib/python3.11/site-packages/torch/utils/data/dataloader.py", line 630, in __next__
    data = self._next_data()
           ^^^^^^^^^^^^^^^^^
  File "/Library/Frameworks/Python.framework/Versions/3.11/lib/python3.11/site-packages/torch/utils/data/dataloader.py", line 1324, in _next_data
    return self._process_data(data)
           ^^^^^^^^^^^^^^^^^^^^^^^^
  File "/Library/Frameworks/Python.framework/Versions/3.11/lib/python3.11/site-packages/torch/utils/data/dataloader.py", line 1370, in _process_data
    data.reraise()
  File "/Library/Frameworks/Python.framework/Versions/3.11/lib/python3.11/site-packages/torch/_utils.py", line 706, in reraise
    raise exception
PIL.UnidentifiedImageError: Caught UnidentifiedImageError in DataLoader worker process 1.
Original Traceback (most recent call last):
  File "/Library/Frameworks/Python.framework/Versions/3.11/lib/python3.11/site-packages/torch/utils/data/_utils/worker.py", line 309, in _worker_loop
    data = fetcher.fetch(index)  # type: ignore[possibly-undefined]
           ^^^^^^^^^^^^^^^^^^^^
  File "/Library/Frameworks/Python.framework/Versions/3.11/lib/python3.11/site-packages/torch/utils/data/_utils/fetch.py", line 52, in fetch
    data = [self.dataset[idx] for idx in possibly_batched_index]
           ^^^^^^^^^^^^^^^^^^^^^^^^^^^^^^^^^^^^^^^^^^^^^^^^^^^^^
  File "/Library/Frameworks/Python.framework/Versions/3.11/lib/python3.11/site-packages/torch/utils/data/_utils/fetch.py", line 52, in <listcomp>
    data = [self.dataset[idx] for idx in possibly_batched_index]
            ~~~~~~~~~~~~^^^^^
  File "/Users/mohamedmafaz/Desktop/PixSketch2Pix/dataset.py", line 24, in __getitem__
    image = np.array(Image.open(file_path))
                     ^^^^^^^^^^^^^^^^^^^^^
  File "/Library/Frameworks/Python.framework/Versions/3.11/lib/python3.11/site-packages/PIL/Image.py", line 3298, in open
    raise UnidentifiedImageError(msg)
PIL.UnidentifiedImageError: cannot identify image file 'image_dataset/landslide/Train/.DS_Store'
