Epoch:  0
  0%|                                                                                                                                      | 0/159 [00:05<?, ?it/s]
Traceback (most recent call last):
  File "/Users/mohamedmafaz/Desktop/PixSketch2Pix/train_with_style_loss.py", line 126, in <module>
    main()
  File "/Users/mohamedmafaz/Desktop/PixSketch2Pix/train_with_style_loss.py", line 115, in main
    train_fn(
  File "/Users/mohamedmafaz/Desktop/PixSketch2Pix/train_with_style_loss.py", line 42, in train_fn
    for idx, (x,z,y) in enumerate(loop):
  File "/Library/Frameworks/Python.framework/Versions/3.11/lib/python3.11/site-packages/tqdm/std.py", line 1178, in __iter__
    for obj in iterable:
  File "/Library/Frameworks/Python.framework/Versions/3.11/lib/python3.11/site-packages/torch/utils/data/dataloader.py", line 630, in __next__
    data = self._next_data()
           ^^^^^^^^^^^^^^^^^
  File "/Library/Frameworks/Python.framework/Versions/3.11/lib/python3.11/site-packages/torch/utils/data/dataloader.py", line 1344, in _next_data
    return self._process_data(data)
           ^^^^^^^^^^^^^^^^^^^^^^^^
  File "/Library/Frameworks/Python.framework/Versions/3.11/lib/python3.11/site-packages/torch/utils/data/dataloader.py", line 1370, in _process_data
    data.reraise()
  File "/Library/Frameworks/Python.framework/Versions/3.11/lib/python3.11/site-packages/torch/_utils.py", line 706, in reraise
    raise exception
cv2.error: Caught error in DataLoader worker process 0.
Original Traceback (most recent call last):
  File "/Library/Frameworks/Python.framework/Versions/3.11/lib/python3.11/site-packages/torch/utils/data/_utils/worker.py", line 309, in _worker_loop
    data = fetcher.fetch(index)  # type: ignore[possibly-undefined]
           ^^^^^^^^^^^^^^^^^^^^
  File "/Library/Frameworks/Python.framework/Versions/3.11/lib/python3.11/site-packages/torch/utils/data/_utils/fetch.py", line 52, in fetch
    data = [self.dataset[idx] for idx in possibly_batched_index]
           ^^^^^^^^^^^^^^^^^^^^^^^^^^^^^^^^^^^^^^^^^^^^^^^^^^^^^
  File "/Library/Frameworks/Python.framework/Versions/3.11/lib/python3.11/site-packages/torch/utils/data/_utils/fetch.py", line 52, in <listcomp>
    data = [self.dataset[idx] for idx in possibly_batched_index]
            ~~~~~~~~~~~~^^^^^
  File "/Users/mohamedmafaz/Desktop/PixSketch2Pix/dataset.py", line 29, in __getitem__
    target_image = config.transform_only_mask(image=target_image)["image"]
                   ^^^^^^^^^^^^^^^^^^^^^^^^^^^^^^^^^^^^^^^^^^^^^^
  File "/Library/Frameworks/Python.framework/Versions/3.11/lib/python3.11/site-packages/albumentations/core/composition.py", line 307, in __call__
    data = t(**data)
           ^^^^^^^^^
  File "/Library/Frameworks/Python.framework/Versions/3.11/lib/python3.11/site-packages/albumentations/core/transforms_interface.py", line 122, in __call__
    return self.apply_with_params(params, **kwargs)
           ^^^^^^^^^^^^^^^^^^^^^^^^^^^^^^^^^^^^^^^^
  File "/Library/Frameworks/Python.framework/Versions/3.11/lib/python3.11/site-packages/albumentations/core/transforms_interface.py", line 134, in apply_with_params
    result = target_function(np.require(arg, requirements=["C_CONTIGUOUS"]), **params)
             ^^^^^^^^^^^^^^^^^^^^^^^^^^^^^^^^^^^^^^^^^^^^^^^^^^^^^^^^^^^^^^^^^^^^^^^^^
  File "/Library/Frameworks/Python.framework/Versions/3.11/lib/python3.11/site-packages/albumentations/augmentations/geometric/resize.py", line 288, in apply
    return fgeometric.resize(img, height=self.height, width=self.width, interpolation=interpolation)
           ^^^^^^^^^^^^^^^^^^^^^^^^^^^^^^^^^^^^^^^^^^^^^^^^^^^^^^^^^^^^^^^^^^^^^^^^^^^^^^^^^^^^^^^^^
  File "/Library/Frameworks/Python.framework/Versions/3.11/lib/python3.11/site-packages/albucore/utils.py", line 118, in wrapped_function
    result = func(img, *args, **kwargs)
             ^^^^^^^^^^^^^^^^^^^^^^^^^^
  File "/Library/Frameworks/Python.framework/Versions/3.11/lib/python3.11/site-packages/albumentations/augmentations/geometric/functional.py", line 349, in resize
    return resize_fn(img)
           ^^^^^^^^^^^^^^
  File "/Library/Frameworks/Python.framework/Versions/3.11/lib/python3.11/site-packages/albucore/utils.py", line 91, in __process_fn
    return process_fn(img, **kwargs)
           ^^^^^^^^^^^^^^^^^^^^^^^^^
cv2.error: OpenCV(4.10.0) /Users/xperience/GHA-Actions-OpenCV/_work/opencv-python/opencv-python/opencv/modules/imgproc/src/resize.cpp:4152: error: (-215:Assertion failed) !ssize.empty() in function 'resize'
